Workbook

Sheet ORIGINAL
D3: Redevances C&S 2026 à Facturer
J5: =SUM(J8:J351) -> 666538
A7: N° Compte | B7: Nom du compte | C7: Nom SF | D7: External ID | E7: Products ID | F7: Article SF | G7: Fréquence facturation | H7: Quantité | I7: Prix unitaire | J7: Montant 2026 | K7: Commentaires | L7: Commentaires
A8: CHVR-01881 | B8: CHEMVIRON | C8: CHEMVIRON sas | D8: 001IV000015S8iQYAS | E8: 01tIV00000GyVCbYAN | F8: Redevance d'utilisation - Tranche 25 ETP - Cas 2 | G8: Annuelle | H8: 1 | I8: 1000 | J8: 1000 | K8: 0 | L8: 0
A9: EIET-01859 | B9: EURO INFORMATION SERVICES | C9: EIS - EURO INFORMATION | D9: 001IV000015SADoYAO | E9: 01tIV00000GOfP6YAL | F9: Redevance d'utilisation - ETP EU | G9: Annuelle | H9: 1 | I9: 1080 | J9: 1080 | K9: 0 | L9: 0
A10: EUFR-01878 | B10: EURIAL ULTRA-FRAIS | C10: EURIAL ULTRA-FRAIS - Château Salins | D10: 001IV000015S2eZYAS | E10: 01tIV00000GyVCbYAN | F10: Redevance d'utilisation - Tranche 25 ETP - Cas 2 | G10: Annuelle | H10: 1 | I10: 3000 | J10: 3000 | K10: 0 | L10: 0
A11: CHRD-01609 | B11: CHARENTAISE DE DECOR | C11: CHARENTAISE DE DECOR | D11: 001IV000015S6a5YAC | E11: 01tIV00000GOfP6YAL | F11: Redevance d'utilisation - ETP EU | G11: Annuelle | H11: 1 | I11: 1000 | J11: 1000 | K11: 0 | L11: 0
A12: VRLF-01972 | B12: VERALLIA France | C12: VERALLIA France | D12: 001IV000015S9GIYA0 | E12: 01tIV00000GOfP6YAL | F12: Redevance d'utilisation - ETP EU | G12: Autre | H12: 1 | I12: 3440 | J12: 3440 | K12: 0 | L12: 0
A13: EPHG-01823 | B13: EPHIGEA GRAIN DE MALICE | C13: EPHIGEA GRAIN DE MALICE sasu | D13: 001IV000015SAHlYAO | E13: 01tIV00000GOfP6YAL | F13: Redevance d'utilisation - ETP EU | G13: Annuelle | H13: 1 | I13: 4200 | J13: 4200 | K13: 0 | L13: 0
A14: EMGP-01816 | B14: EM LYON EMG | C14: EMG-EARLY MAKERS GROUP | D14: 001IV000015SAHkYAO | E14: 01tIV00000GyVCbYAN | F14: Redevance d'utilisation - Tranche 25 ETP - Cas 2 | H14: 1 | I14: 1000 | J14: 1000
A15: SFRT-01772 | B15: SEYFERT | C15: SEYFERT SAS | D15: 001IV000015RyDnYAK | E15: 01tIV00000GyVCbYAN | F15: Redevance d'utilisation - Tranche 25 ETP - Cas 2 | G15: Annuelle | H15: 1 | I15: 4000 | J15: 4000 | K15: 0 | L15: 0
A16: IPSA-01585 | B16: INTERNATIONAL PAPER France | C16: INTERNATIONAL PAPER France | D16: 001IV000015SAFhYAO | E16: 01tIV00000GOfP1YAL | F16: Redevance d'utilisation - Tranche 25 ETP - Cas 1 | G16: Annuelle | H16: 1 | I16: 2000 | J16: 2000 | K16: 0 | L16: 0
A17: GCPC-01584 | B17: CHRYSO FRANCE | C17: CHRYSO FRANCE (ex GCP PRODUITS DE CONSTRUCTION) | D17: 001IV000015S2eRYAS | E17: 01tIV00000GyVCbYAN | F17: Redevance d'utilisation - Tranche 25 ETP - Cas 2 | G17: Annuelle | H17: 1 | I17: 1000 | J17: 1000 | K17: 0 | L17: 0
A18: ABSD-01564 | B18: ABRISUD | C18: ABRISUD | D18: 001IV000015S6ZxYAK | E18: 01tIV00000GOfP6YAL | F18: Redevance d'utilisation - ETP EU | G18: Annuelle | H18: 1 | I18: 1800 | J18: 1800 | K18: 0 | L18: 0
A19: ACIA-01692 | B19: ACIAL | C19: ACIAL | D19: 001IV000015S85xYAC | E19: 01tIV00000GyVCbYAN | F19: Redevance d'utilisation - Tranche 25 ETP - Cas 2 | G19: Annuelle | H19: 1 | I19: 1000 | J19: 1000 | K19: 0 | L19: 0
A20: ALMG-01848 | B20: ALMA GROUPE | C20: ALMA GROUPE | D20: 001IV000015RyDjYAK | E20: 01tIV00000GyVCbYAN | F20: Redevance d'utilisation - Tranche 25 ETP - Cas 2 | G20: Annuelle | H20: 1 | I20: 9000 | J20: 9000 | K20: 0 | L20: 0
A21: ANGD-01672 | B21: ANGDM | C21: ANGDM | D21: 001IV000015S50QYAS | E21: 01tIV00000GyVCbYAN | F21: Redevance d'utilisation - Tranche 25 ETP - Cas 2 | G21: Annuelle | H21: 1 | I21: 1000 | J21: 1000
A22: AMPR-01765 | B22: SOFIVO | C22: ARMOR PROTEINES | D22: 001IV000015RewHYAS | E22: 01tIV00000GyVCbYAN | F22: Redevance d'utilisation - Tranche 25 ETP - Cas 2 | G22: Annuelle | H22: 1 | I22: 3000 | J22: 3000 | K22: 0 | L22: 0
A23: ATSX-01481 | B23: APPLICATION TRAVAUX SPECIAUX | C23: ATS | D23: 001IV000015Rew7YAC | E23: 01tIV00000GOfP6YAL | F23: Redevance d'utilisation - ETP EU | G23: Annuelle | H23: 1 | I23: 1800 | J23: 1800 | K23: 0 | L23: 0
A24: AXGR-01774 | B24: AXE GROUP | C24: AXE GROUP | D24: 001IV000015S50NYAS | E24: 01tIV00000GyVCbYAN | F24: Redevance d'utilisation - Tranche 25 ETP - Cas 2 | G24: Annuelle | H24: 1 | I24: 1000 | J24: 1000 | K24: 0 | L24: 0
A25: BPEF-01789 | B25: BALL PACKAGING EUROPE | C25: BALL PACKAGING GROUPE | D25: 001IV000015RhU5YAK | E25: 01tIV00000GOfP6YAL | F25: Redevance d'utilisation - ETP EU | G25: Annuelle | H25: 1 | I25: 1080 | J25: 1080 | K25: 0 | L25: 0
A26: BBGR-01651 | B26: BARBIER PLASTIQUES | C26: BARBIER GROUPE | D26: 001IV000015RzTfYAK | E26: 01tIV00000GyVCbYAN | F26: Redevance d'utilisation - Tranche 25 ETP - Cas 2 | G26: Annuelle | H26: 1 | I26: 8000 | J26: 8000 | K26: 0 | L26: 0
A27: BSFA-01740 | B27: BASF AGRI PRODUCTION | C27: BASF AGRIPRODUCTION | D27: 001IV000015RyDgYAK | E27: 01tIV00000GyVCbYAN | F27: Redevance d'utilisation - Tranche 25 ETP - Cas 2 | G27: Annuelle | H27: 1 | I27: 2000 | J27: 2000 | K27: 0 | L27: 0
A28: BICR-01561 | B28: BIC RASOIRS | C28: BIC RASOIRS | D28: 001IV000015S50CYAS | E28: 01tIV00000GyVCbYAN | F28: Redevance d'utilisation - Tranche 25 ETP - Cas 2 | G28: Annuelle | H28: 1 | I28: 1000 | J28: 1000 | K28: 0 | L28: 0
A29: BIOH-01734 | B29: BIO HABITAT | C29: BIO HABITAT | D29: 001IV000015S6a8YAC | E29: 01tIV00000GOfP1YAL | F29: Redevance d'utilisation - Tranche 25 ETP - Cas 1 | G29: Annuelle | H29: 1 | I29: 2500 | J29: 2500 | K29: 0 | L29: 0
A30: BLCH-01662 | B30: BLANCHON SA | C30: BLANCHON (GROUPE) | D30: 001IV000015RewMYAS | E30: 01tIV00000GyVCbYAN | F30: Redevance d'utilisation - Tranche 25 ETP - Cas 2 | G30: Annuelle | H30: 1 | I30: 3000 | J30: 3000 | K30: 0 | L30: 0
A31: BGRD-01647 | B31: BONGARD | C31: BONGARD | D31: 001IV000015S2eNYAS | E31: 01tIV00000GyVCbYAN | F31: Redevance d'utilisation - Tranche 25 ETP - Cas 2 | G31: Annuelle | H31: 1 | I31: 1000 | J31: 1000 | K31: 0 | L31: 0
A32: BNFY-01575 | B32: BONNEFOY SAS | C32: BONNEFOY SAS | D32: 001IV000015S8imYAC | E32: 01tIV00000GyVCbYAN | F32: Redevance d'utilisation - Tranche 25 ETP - Cas 2 | G32: Annuelle | H32: 1 | I32: 2000 | J32: 2000 | K32: 0 | L32: 0
A33: CEKC-01875 | B33: C ET K COMPONENTS SAS | C33: C&K COMPONENTS SAS | D33: 001IV000015S8iPYAS | E33: 01tIV00000GyVCbYAN | F33: Redevance d'utilisation - Tranche 25 ETP - Cas 2 | G33: Annuelle | H33: 1 | I33: 2000 | J33: 2000 | K33: 0 | L33: 0
... A41: DNAG-01749 | B41: DIANA | C41: DIANA GROUP | D41: 001IV000015S8j4YAC | E41: 01tIV00000GOfP6YAL | F41: Redevance d'utilisation - ETP EU | G41: Annuelle | H41: 1 | I41: 3840 | J41: 3840 | K41: 0 | L41: 0
A42: DKFR-01494 | B42: DOKA FRANCE | C42: DOKA FRANCE | D42: 001IV000015Rew8YAC | E42: 01tIV00000GOfP6YAL | F42: Redevance d'utilisation - ETP EU | G42: Annuelle | H42: 1 | I42: 2232 | J42: 2232
A43: DSPX-01537 | B43: DSP | C43: DSP | D43: 001IV000015RyDhYAK | E43: 01tIV00000GyVCbYAN | F43: Redevance d'utilisation - Tranche 25 ETP - Cas 2 | G43: Annuelle | H43: 1 | I43: 1000 | J43: 1000 | K43: 0 | L43: 0
A44: ELDN-01899 | B44: ELYDAN SAS | C44: ELYDAN sas | D44: 001IV000015SAI9YAO | E44: 01tIV00000GyVCbYAN | F44: Redevance d'utilisation - Tranche 25 ETP - Cas 2 | G44: Annuelle | H44: 1 | I44: 3000 | J44: 3000 | K44: 0 | L44: 0
A45: FLDT-01645 | B45: FIELDTURF TARKETT | C45: FIELDTURF TARKETT | D45: 001IV000015S2eDYAS | E45: 01tIV00000GOfP1YAL | F45: Redevance d'utilisation - Tranche 25 ETP - Cas 1 | G45: Annuelle | H45: 1 | I45: 1000 | J45: 1000 | K45: 0 | L45: 0
A46: FNLM-01536 | B46: FINE LAME | C46: FINE LAME | D46: 001IV000015S6a1YAC | E46: 01tIV00000GyVCbYAN | F46: Redevance d'utilisation - Tranche 25 ETP - Cas 2 | G46: Annuelle | H46: 1 | I46: 1000 | J46: 1000 | K46: 0 | L46: 0
A47: FLIP-01667 | B47: FLIP | C47: FLIP SAS | D47: 001IV000015S2ePYAS | E47: 01tIV00000GyVCbYAN | F47: Redevance d'utilisation - Tranche 25 ETP - Cas 2 | G47: Annuelle | H47: 1 | I47: 1000 | J47: 1000 | K47: 0 | L47: 0
A48: FMCF-01656 | B48: GROUPE FMC | C48: FMC FRANCE | D48: 001IV000015S2eSYAS | E48: 01tIV00000GOfP6YAL | F48: Redevance d'utilisation - ETP EU | G48: Annuelle | H48: 1 | I48: 2232 | J48: 2232 | K48: 0 | L48: 0
A49: FRCS-01805 | B49: SISLEY INDUSTRIE | C49: FRANCOS - (SISLEY) | D49: 001IV000015RyDwYAK | E49: 01tIV00000GyVCbYAN | F49: Redevance d'utilisation - Tranche 25 ETP - Cas 2 | G49: Annuelle | H49: 1 | I49: 1000 | J49: 1000 | K49: 0 | L49: 0
A50: FRST-01862 | B50: FREUDENBERG SEALING TECHNOLOGIES SA | C50: FREUDENBERG SEALING TECHNOLOGIES sas | D50: 001IV000015RyE1YAK | E50: 01tIV00000GyVCbYAN | F50: Redevance d'utilisation - Tranche 25 ETP - Cas 2 | G50: Annuelle | H50: 1 | I50: 1000 | J50: 1000 | K50: 0 | L50: 0
A51: GHSF-01558 | B51: GEORGES HELFER | C51: GEORGES HELFER | D51: 001IV000015S50BYAS | E51: 01tIV00000GOfP6YAL | F51: Redevance d'utilisation - ETP EU | G51: Annuelle | H51: 1 | I51: 4120 | J51: 4120 | K51: 0 | L51: 0
...

Sheet DOCUMENT DE TRAVAIL
D3: Redevances C&S 2026 à Facturer
AP5: =SUM(AP8:AP350) -> 641538
A7: N° Compte | B7: Nom du compte | C7: Nom SF | D7: External ID | E7: Products ID | F7: Article SF | G7: Line description | H7: Billing schedule | I7: Terme | J7: Billling start date | K7: End date | L7: Activity | M7: Offer | N7: Closing Date | O7: Legacy ID | P7: VAT Number | Q7: Registration number | R7: Invoice sending method | S7: Send invoice to | T7: Payment method | U7: Charge map type | V7: Billing Business Name | W7: Billing Department | X7: Billing Street | Y7: Billing City | Z7: Billing Postal code | AA7: Billing instruction | AB7: Billing conditions | AC7: PO Required? | AD7: PO Reference | AE7: PO Request Date | AF7: Shipping Business Name | AG7: Shipping Department | AH7: Shipping street | AI7: Shipping City | AJ7: Billing Contact ID | AK7: Billing Contact | AL7: Cash collection ID | AM7: Cash collection Contact | AN7: Quantité | AO7: Prix unitaire | AP7: Montant 2026 | AQ7: Commentaires | AR7: Commentaires
A8: PLCH-01717 | B8: PLACOPLATRE CHAMBERY | C8: PLACOPLATRE CHAMBERY | D8: 001IV000015S8iwYAC | E8: 01tIV00000GyVCbYAN | F8: Redevance d'utilisation - Tranche 25 ETP - Cas 2 | H8: Annual | I8: In advance | J8: 46023 | K8: 46387 | L8: Pixid France | M8: Pack C&S | N8: 46023 | O8: =VLOOKUP(D8,records!$A:$U,10,FALSE) -> 001SZ0000017fU7YAI | P8: =VLOOKUP(D8,records!$A:$V,20,FALSE) -> FR95729800706 | Q8: =VLOOKUP(D8,records!$A:$V,12,FALSE) -> 72 980 070 600 040 | R8: Email | S8: =VLOOKUP(D8,records!$A:$W,19,FALSE) -> 0nly.invoices.placoplatre@saint-gobain.com | T8: Transfer | U8: Renewal | V8: =VLOOKUP($D8,records!$A:$V,3,FALSE) -> PLACOPLATRE sa - Usine Placo de Chambéry | W8: =IFERROR(VLOOKUP($D8,records!$A:$V,6,FALSE),) -> Ressources Humaines | X8: =VLOOKUP($D8,records!$A:$V,9,FALSE) -> Z.I de Bissy - 456 rue Emile Romanet | Y8: =VLOOKUP($D8,records!$A:$V,4,FALSE) -> CHAMBERY | Z8: =VLOOKUP($D8,records!$A:$V,7,FALSE) -> 73026 | AA8: Redevance 2026 | AB8: =VLOOKUP(O8,'records (2)'!$A:$Z,8,FALSE) -> 30 | AC8: FALSE | AF8: =VLOOKUP($D8,records!$A:$V,13,FALSE) -> PLACOPLATRE sa - Usine Placo de Chambéry | AG8: =VLOOKUP($D8,records!$A:$V,16,FALSE) -> Facture originale électronique à | AH8: =VLOOKUP($D8,records!$A:$V,19,FALSE) -> 0nly.invoices.placoplatre@saint-gobain.com | AI8: =VLOOKUP($D8,records!$A:$V,14,FALSE) -> . | AJ8: =VLOOKUP($O8,'records (2)'!$A:$Z,14,FALSE) -> 003IV000010tSmVYAU | AK8: =VLOOKUP($O8,'records (2)'!$A:$Z,15,FALSE) -> Lucie GRANGER | AL8: =VLOOKUP($O8,'records (2)'!$A:$Z,10,FALSE) -> 003IV000010tSmVYAU | AM8: =VLOOKUP($O8,'records (2)'!$A:$Z,11,FALSE) -> Lucie GRANGER | AN8: 1 | AO8: 1000 | AP8: 1000 | AQ8: 0 | AR8: 0
A9: SABG-01649 | B9: GROUPE SAB | C9: SAB GROUPE | D9: 001IV000015SAHsYAO | E9: 01tIV00000GOfP1YAL | F9: Redevance d'utilisation - Tranche 25 ETP - Cas 1 | H9: Annual | I9: In advance | J9: 46023 | K9: 46387 | L9: Pixid France | M9: Pack C&S | N9: 46023 | O9: =VLOOKUP(D9,records!$A:$U,10,FALSE) -> 0012p00004TwEORAA3 | P9: =VLOOKUP(D9,records!$A:$V,20,FALSE) -> FR46305148884 | Q9: =VLOOKUP(D9,records!$A:$V,12,FALSE) -> 30 514 888 400 029 | R9: Paper | T9: Transfer | U9: Renewal | V9: =VLOOKUP($D9,records!$A:$V,3,FALSE) -> GROUPE SAB - FINANCIERE D'AZOLETTE sa | X9: =VLOOKUP($D9,records!$A:$V,9,FALSE) -> 1077 Route des 4 vents | Y9: =VLOOKUP($D9,records!$A:$V,4,FALSE) -> BELMONT DE LA LOIRE | Z9: =VLOOKUP($D9,records!$A:$V,7,FALSE) -> 42670 | AA9: Redevance 2026 | AB9: =VLOOKUP(O9,'records (2)'!$A:$Z,8,FALSE) -> 30 | AC9: FALSE | AF9: =VLOOKUP($D9,records!$A:$V,13,FALSE) -> GROUPE SAB - FINANCIERE D'AZOLETTE sa | AH9: =VLOOKUP($D9,records!$A:$V,19,FALSE) -> 1077 Route des 4 vents | AI9: =VLOOKUP($D9,records!$A:$V,14,FALSE) -> BELMONT DE LA LOIRE | AJ9: =VLOOKUP($O9,'records (2)'!$A:$Z,14,FALSE) -> 003IV000010tTsfYAE | AK9: =VLOOKUP($O9,'records (2)'!$A:$Z,15,FALSE) -> Christine GROSSELIN | AL9: =VLOOKUP($O9,'records (2)'!$A:$Z,10,FALSE) -> 003IV000010tTsfYAE | AM9: =VLOOKUP($O9,'records (2)'!$A:$Z,11,FALSE) -> Christine GROSSELIN | AN9: 1 | AO9: 1000 | AP9: 1000 | AQ9: 0 | AR9: 0
A10: HB76-01741 | B10: HABITAT 76 | C10: HABITAT 76 | D10: 001IV000015SAI5YAO | E10: 01tIV00000GyVCbYAN | F10: Redevance d'utilisation - Tranche 25 ETP - Cas 2 | H10: Annual | I10: In advance | J10: 46023 | K10: 46387 | L10: Pixid France | M10: Pack C&S | N10: 46023 | O10: =VLOOKUP(D10,records!$A:$U,10,FALSE) -> 001SZ000002Sv8iYAC | P10: =VLOOKUP(D10,records!$A:$V,20,FALSE) -> FR36781107446 | Q10: =VLOOKUP(D10,records!$A:$V,12,FALSE) -> 78 110 744 600 069 | R10: Paper | T10: Transfer | U10: Renewal | V10: =VLOOKUP($D10,records!$A:$V,3,FALSE) -> OFFICE PUBLIC DE L'HABITAT DU DEPARTEMENT DE SEINE-MARITIME | W10: =IFERROR(VLOOKUP($D10,records!$A:$V,6,FALSE),) -> HABITAT 76 - Service RHEC | X10: =VLOOKUP($D10,records!$A:$V,9,FALSE) -> 112 Boulevard d'Orléans | Y10: =VLOOKUP($D10,records!$A:$V,4,FALSE) -> ROUEN | Z10: =VLOOKUP($D10,records!$A:$V,7,FALSE) -> 76100 | AA10: Redevance 2026 | AB10: =VLOOKUP(O10,'records (2)'!$A:$Z,8,FALSE) -> 30 | AC10: =VLOOKUP(O10,'records (4)'!$A:$C,3,FALSE) -> TRUE | AD10: YES | AE10: 46023 | AF10: =VLOOKUP($D10,records!$A:$V,13,FALSE) -> OFFICE PUBLIC DE L'HABITAT DU DEPARTEMENT DE SEINE-MARITIME | AG10: =VLOOKUP($D10,records!$A:$V,16,FALSE) -> HABITAT 76 - Service RHEC | AH10: =VLOOKUP($D10,records!$A:$V,19,FALSE) -> 112 Boulevard d'Orléans | AI10: =VLOOKUP($D10,records!$A:$V,14,FALSE) -> ROUEN | AJ10: =VLOOKUP($O10,'records (2)'!$A:$Z,14,FALSE) -> 003IV000010rLj2YAE | AK10: =VLOOKUP($O10,'records (2)'!$A:$Z,15,FALSE) -> Mélissa AMGHAR | AL10: =VLOOKUP($O10,'records (2)'!$A:$Z,10,FALSE) -> 003IV000010rLj2YAE | AM10: =VLOOKUP($O10,'records (2)'!$A:$Z,11,FALSE) -> Mélissa AMGHAR | AN10: 1 | AO10: 3000 | AP10: 3000 | AQ10: 0 | AR10: 0
A11: TTPK-01534 | B11: TETRAPAK | C11: TETRAPAK | D11: 001IV000015S2eCYAS | E11: 01tIV00000GOfP1YAL | F11: Redevance d'utilisation - Tranche 25 ETP - Cas 1 | H11: Annual | I11: In advance | J11: 46023 | K11: 46387 | L11: Pixid France | M11: Pack C&S | N11: 46023 | O11: =VLOOKUP(D11,records!$A:$U,10,FALSE) -> 0012p00004OKNMCAA5 | P11: =VLOOKUP(D11,records!$A:$V,20,FALSE) -> FR30017150285 | Q11: =VLOOKUP(D11,records!$A:$V,12,FALSE) -> 1 715 028 500 066 | R11: Email | S11: =VLOOKUP(D11,records!$A:$U,19,FALSE) -> 144.accountspayable@ap.tetrapak.com | T11: Transfer | U11: Renewal | V11: =VLOOKUP($D11,records!$A:$V,3,FALSE) -> PAPETERIES DE DIJON snc | X11: =VLOOKUP($D11,records!$A:$V,9,FALSE) -> 3 rue Romelet | Y11: =VLOOKUP($D11,records!$A:$V,4,FALSE) -> LONGVIC | Z11: =VLOOKUP($D11,records!$A:$V,7,FALSE) -> 21600 | AA11: Redevance 2026 | AB11: =VLOOKUP(O11,'records (2)'!$A:$Z,8,FALSE) -> 30 | AC11: FALSE | AF11: =VLOOKUP($D11,records!$A:$V,13,FALSE) -> PAPETERIES DE DIJON snc | AG11: Facture originale électronique à | AH11: =VLOOKUP($D11,records!$A:$V,19,FALSE) -> 144.accountspayable@ap.tetrapak.com | AI11: =VLOOKUP($D11,records!$A:$V,14,FALSE) -> . | AJ11: =VLOOKUP($O11,'records (2)'!$A:$Z,14,FALSE) -> 003IV000010tRVxYAM | AK11: =VLOOKUP($O11,'records (2)'!$A:$Z,15,FALSE) -> Monika HORVATH (Accounting) | AL11: =VLOOKUP($O11,'records (2)'!$A:$Z,10,FALSE) -> 003IV000010tRVxYAM | AM11: =VLOOKUP($O11,'records (2)'!$A:$Z,11,FALSE) -> Monika HORVATH (Accounting) | AN11: 1 | AO11: 500 | AP11: 500 | AQ11: 0 | AR11: 0
A12: SNDM-01975 | B12: SNCF DOMAINE MATERIEL | C12: SNCF DOMAINE MATERIEL | D12: 001IV000015S541YAC | E12: 01tIV00000GOfP1YAL | F12: Redevance d'utilisation - Tranche 25 ETP - Cas 1 | H12: Annual | I12: In advance | J12: 46023 | K12: 46387 | L12: Pixid France | M12: Pack C&S | N12: 46023 | O12: =VLOOKUP(D12,records!$A:$U,10,FALSE) -> 001SZ00000DoG8ZYAV | P12: =VLOOKUP(D12,records!$A:$V,20,FALSE) -> FR55518697685 | Q12: =VLOOKUP(D12,records!$A:$V,12,FALSE) -> 51 869 768 502 383 | R12: Paper | T12: Transfer | U12: Renewal | V12: =VLOOKUP($D12,records!$A:$V,3,FALSE) -> SNCF DOMAINE MATERIEL | X12: =VLOOKUP($D12,records!$A:$V,9,FALSE) -> 16 rue Simone Veil | Y12: =VLOOKUP($D12,records!$A:$V,4,FALSE) -> SAINT-OUEN-SUR-SEINE | Z12: =VLOOKUP($D12,records!$A:$V,7,FALSE) -> 93400 | AA12: Redevance 2026 | AB12: =VLOOKUP(O12,'records (2)'!$A:$Z,8,FALSE) -> 30 | AC12: FALSE | AF12: =VLOOKUP($D12,records!$A:$V,13,FALSE) -> SNCF DOMAINE MATERIEL | AH12: =VLOOKUP($D12,records!$A:$V,19,FALSE) -> 16 rue Simone Veil | AI12: =VLOOKUP($D12,records!$A:$V,14,FALSE) -> SAINT-OUEN-SUR-SEINE | AJ12: =VLOOKUP($O12,'records (2)'!$A:$Z,14,FALSE) -> 003IV000010tNmEYAU | AK12: =VLOOKUP($O12,'records (2)'!$A:$Z,15,FALSE) -> Marine BOSCH | AL12: =VLOOKUP($O12,'records (2)'!$A:$Z,10,FALSE) -> 003IV000010tSjCYAU | AM12: =VLOOKUP($O12,'records (2)'!$A:$Z,11,FALSE) -> Lolita DE VITI | AN12: 1 | AO12: 1000 | AP12: 1000 | AQ12: 0 | AR12: 0
A13: ANTS-01879 | B13: AGCE NAT DES TITRES SECURISES | C13: ANTS | D13: 001IV000015S8izYAC | E13: 01tIV00000GOfP1YAL | F13: Redevance d'utilisation - Tranche 25 ETP - Cas 1 | H13: Annual | I13: In advance | J13: 46023 | K13: 46387 | L13: Pixid France | M13: Pack C&S | N13: 46023 | O13: =VLOOKUP(D13,records!$A:$U,10,FALSE) -> 001SZ000001s7vFYAQ | P13: =VLOOKUP(D13,records!$A:$V,20,FALSE) -> FR55130003262 | Q13: =VLOOKUP(D13,records!$A:$V,12,FALSE) -> 13 000 326 200 024 | R13: Paper | T13: Transfer | U13: Renewal | V13: =VLOOKUP($D13,records!$A:$V,3,FALSE) -> AGENCE NATIONALE DES TITRES SECURISES | X13: =VLOOKUP($D13,records!$A:$V,9,FALSE) -> 18 Rue Irénee Carré | Y13: =VLOOKUP($D13,records!$A:$V,4,FALSE) -> CHARLEVILLE-MEZIERES | Z13: =VLOOKUP($D13,records!$A:$V,7,FALSE) -> 8800 | AA13: Redevance 2026 | AB13: =VLOOKUP(O13,'records (2)'!$A:$Z,8,FALSE) -> 30 | AC13: =VLOOKUP(O13,'records (4)'!$A:$C,3,FALSE) -> TRUE | AD13: YES | AE13: 46023 | AF13: =VLOOKUP($D13,records!$A:$V,13,FALSE) -> AGENCE NATIONALE DES TITRES SECURISES | AH13: =VLOOKUP($D13,records!$A:$V,19,FALSE) -> 18 Rue Irénee Carré | AI13: =VLOOKUP($D13,records!$A:$V,14,FALSE) -> CHARLEVILLE-MEZIERES | AJ13: =VLOOKUP($O13,'records (2)'!$A:$Z,14,FALSE) -> 003IV000010tSnVYAU | AK13: =VLOOKUP($O13,'records (2)'!$A:$Z,15,FALSE) -> Service facturation | AL13: =VLOOKUP($O13,'records (2)'!$A:$Z,10,FALSE) -> 003IV000010tSnVYAU | AM13: =VLOOKUP($O13,'records (2)'!$A:$Z,11,FALSE) -> Service facturation | AN13: 1 | AO13: 500 | AP13: 500 | AQ13: 0 | AR13: 0
A14: MTBL-01521 | B14: MONT BLANC | C14: MONT BLANC | D14: 001IV000015S2eOYAS | E14: 01tIV00000GyVCbYAN | F14: Redevance d'utilisation - Tranche 25 ETP - Cas 2 | H14: Annual | I14: In advance | J14: 46023 | K14: 46387 | L14: Pixid France | M14: Pack C&S | N14: 46023 | O14: =VLOOKUP(D14,records!$A:$U,10,FALSE) -> 0012p00004MTowVAAT | P14: =VLOOKUP(D14,records!$A:$V,20,FALSE) -> FR56448954362 | Q14: =VLOOKUP(D14,records!$A:$V,12,FALSE) -> 44 895 436 200 043 | R14: Paper | T14: Transfer | U14: Renewal | V14: =VLOOKUP($D14,records!$A:$V,3,FALSE) -> MONT BLANC sas | W14: =IFERROR(VLOOKUP($D14,records!$A:$V,6,FALSE),) -> RH | X14: =VLOOKUP($D14,records!$A:$V,9,FALSE) -> 2 rue du Capitaine Rex Combs | Y14: =VLOOKUP($D14,records!$A:$V,4,FALSE) -> CHEF DU PONT | Z14: =VLOOKUP($D14,records!$A:$V,7,FALSE) -> 50480 | AA14: Redevance 2026 | AB14: =VLOOKUP(O14,'records (2)'!$A:$Z,8,FALSE) -> 30 | AC14: FALSE | AF14: =VLOOKUP($D14,records!$A:$V,13,FALSE) -> MONT BLANC sas | AH14: =VLOOKUP($D14,records!$A:$V,19,FALSE) -> 2 rue du Capitaine Rex Combs | AI14: =VLOOKUP($D14,records!$A:$V,14,FALSE) -> CHEF DU PONT | AJ14: =VLOOKUP($O14,'records (2)'!$A:$Z,14,FALSE) -> 003IV000010t1w0YAA | AK14: =VLOOKUP($O14,'records (2)'!$A:$Z,15,FALSE) -> Lise BAJIC | AL14: =VLOOKUP($O14,'records (2)'!$A:$Z,10,FALSE) -> 003IV000010t1w0YAA | AM14: =VLOOKUP($O14,'records (2)'!$A:$Z,11,FALSE) -> Lise BAJIC | AN14: 1 | AO14: 2000 | AP14: 2000 | AQ14: 0 | AR14: 0
A15: FRFM-01755 | B15: Groupe SFPI | C15: Groupe SFPI | D15: 001IV000015S868YAC | E15: 01tIV00000GOfP1YAL | F15: Redevance d'utilisation - Tranche 25 ETP - Cas 1 | H15: Annual | I15: In advance | J15: 46023 | K15: 46387 | L15: Pixid France | M15: Pack C&S | N15: 46023 | O15: =VLOOKUP(D15,records!$A:$U,10,FALSE) -> 001SZ000003jyZNYAY | P15: =VLOOKUP(D15,records!$A:$V,20,FALSE) -> FR26393588595 | Q15: =VLOOKUP(D15,records!$A:$V,12,FALSE) -> 39 358 859 500 065 | R15: Paper | T15: Transfer | U15: Renewal | V15: =VLOOKUP($D15,records!$A:$V,3,FALSE) -> GROUPE SFPI sa | X15: =VLOOKUP($D15,records!$A:$V,9,FALSE) -> 20 Rue de L'Arc de Triomphe | Y15: =VLOOKUP($D15,records!$A:$V,4,FALSE) -> PARIS | Z15: =VLOOKUP($D15,records!$A:$V,7,FALSE) -> 75017 | AA15: Redevance 2026 | AB15: =VLOOKUP(O15,'records (2)'!$A:$Z,8,FALSE) -> 30 | AC15: FALSE | AF15: =VLOOKUP($D15,records!$A:$V,13,FALSE) -> GROUPE SFPI sa | AH15: =VLOOKUP($D15,records!$A:$V,19,FALSE) -> 20 Rue de L'Arc de Triomphe | AI15: =VLOOKUP($D15,records!$A:$V,14,FALSE) -> PARIS | AJ15: =VLOOKUP($O15,'records (2)'!$A:$Z,14,FALSE) -> 003IV000010tIdSYAU | AK15: =VLOOKUP($O15,'records (2)'!$A:$Z,15,FALSE) -> Laura DI BARTOLOMEO | AL15: =VLOOKUP($O15,'records (2)'!$A:$Z,10,FALSE) -> 003IV000010tIdSYAU | AM15: =VLOOKUP($O15,'records (2)'!$A:$Z,11,FALSE) -> Laura DI BARTOLOMEO | AN15: 1 | AO15: 2500 | AP15: 2500 | AQ15: 0 | AR15: 0
A16: BCRT-01784 | B16: BACCARAT | C16: BACCARAT | D16: 001IV000015SAI6YAO | E16: 01tIV00000GOfP1YAL | F16: Redevance d'utilisation - Tranche 25 ETP - Cas 1 | H16: Annual | I16: In advance | J16: 46023 | K16: 46387 | L16: Pixid France | M16: Pack C&S | N16: 46023 | O16: =VLOOKUP(D16,records!$A:$U,10,FALSE) -> 001SZ000004kQ5GYAU | P16: =VLOOKUP(D16,records!$A:$V,20,FALSE) -> FR86760800060 | Q16: =VLOOKUP(D16,records!$A:$V,12,FALSE) -> 76 080 006 000 013 | R16: Paper | T16: Transfer | U16: Renewal | V16: =VLOOKUP($D16,records!$A:$V,3,FALSE) -> BACCARAT sa | X16: =VLOOKUP($D16,records!$A:$V,9,FALSE) -> 20 Rue des Cristalleries | Y16: =VLOOKUP($D16,records!$A:$V,4,FALSE) -> BACCARAT | Z16: =VLOOKUP($D16,records!$A:$V,7,FALSE) -> 54120 | AA16: Redevance 2026 | AB16: =VLOOKUP(O16,'records (2)'!$A:$Z,8,FALSE) -> 30 | AC16: FALSE | AF16: =VLOOKUP($D16,records!$A:$V,13,FALSE) -> BACCARAT sa | AH16: =VLOOKUP($D16,records!$A:$V,19,FALSE) -> 20 Rue des Cristalleries | AI16: =VLOOKUP($D16,records!$A:$V,14,FALSE) -> BACCARAT | AJ16: =VLOOKUP($O16,'records (2)'!$A:$Z,14,FALSE) -> 003IV000010su8iYAA | AK16: =VLOOKUP($O16,'records (2)'!$A:$Z,15,FALSE) -> Compta Fournisseurs BACCARAT | AL16: =VLOOKUP($O16,'records (2)'!$A:$Z,10,FALSE) -> 003IV000010su8iYAA | AM16: =VLOOKUP($O16,'records (2)'!$A:$Z,11,FALSE) -> Compta Fournisseurs BACCARAT | AN16: 1 | AO16: 500 | AP16: 500 | AQ16: 0 | AR16: 0
A17: MCBD-01903 | B17: MCBRIDE S.A.S | C17: MC BRIDE SAS | D17: 001IV000015RyE0YAK | E17: 01tIV00000GyVCbYAN | F17: Redevance d'utilisation - Tranche 25 ETP - Cas 2 | H17: Annual | I17: In advance | J17: 46023 | K17: 46387 | L17: Pixid France | M17: Pack C&S | N17: 46023 | O17: =VLOOKUP(D17,records!$A:$U,10,FALSE) -> 001SZ000008J7IzYAK | P17: =VLOOKUP(D17,records!$A:$V,20,FALSE) -> FR10391159548 | Q17: =VLOOKUP(D17,records!$A:$V,12,FALSE) -> 39 115 954 800 034 | R17: Paper | T17: Transfer | U17: Renewal | V17: =VLOOKUP($D17,records!$A:$V,3,FALSE) -> McBRIDE S.A.S | X17: =VLOOKUP($D17,records!$A:$V,9,FALSE) -> 20 Rue Gustave Flaubert | Y17: =VLOOKUP($D17,records!$A:$V,4,FALSE) -> MOYAUX | Z17: =VLOOKUP($D17,records!$A:$V,7,FALSE) -> 14590 | AA17: Redevance 2026 | AB17: =VLOOKUP(O17,'records (2)'!$A:$Z,8,FALSE) -> 45 | AC17: =VLOOKUP(O17,'records (4)'!$A:$C,3,FALSE) -> TRUE | AD17: YES | AE17: 46023 | AF17: =VLOOKUP($D17,records!$A:$V,13,FALSE) -> McBRIDE S.A.S | AH17: =VLOOKUP($D17,records!$A:$V,19,FALSE) -> 20 Rue Gustave Flaubert | AI17: =VLOOKUP($D17,records!$A:$V,14,FALSE) -> MOYAUX | AJ17: =VLOOKUP($O17,'records (2)'!$A:$Z,14,FALSE) -> 003IV000010tJZpYAM | AK17: =VLOOKUP($O17,'records (2)'!$A:$Z,15,FALSE) -> Aurélie PETIT | AL17: =VLOOKUP($O17,'records (2)'!$A:$Z,10,FALSE) -> 003IV000010tJZpYAM | AM17: =VLOOKUP($O17,'records (2)'!$A:$Z,11,FALSE) -> Aurélie PETIT | AN17: 1 | AO17: 3000 | AP17: 3000 | AQ17: 0 | AR17: 0
A18: PSTC-01541 | B18: PASTACORP | C18: PASTACORP (PACK C&S) | D18: 001IV000015SAFeYAO | E18: 01tIV00000GOfP1YAL | F18: Redevance d'utilisation - Tranche 25 ETP - Cas 1 | H18: Annual | I18: In advance | J18: 46023 | K18: 46387 | L18: Pixid France | M18: Pack C&S | N18: 46023 | O18: =VLOOKUP(D18,records!$A:$U,10,FALSE) -> 0012p00004Nh7mSAAR | P18: =VLOOKUP(D18,records!$A:$V,20,FALSE) -> FR88829809482 | Q18: =VLOOKUP(D18,records!$A:$V,12,FALSE) -> 82 980 948 200 039 | R18: Paper | T18: Transfer | U18: Renewal | V18: =VLOOKUP($D18,records!$A:$V,3,FALSE) -> PASTACORP TRAITEUR sas | W18: =IFERROR(VLOOKUP($D18,records!$A:$V,6,FALSE),) -> Ressources Humaines | X18: =VLOOKUP($D18,records!$A:$V,9,FALSE) -> 21 Rue de Borolan | Y18: =VLOOKUP($D18,records!$A:$V,4,FALSE) -> CHAMBERY | Z18: =VLOOKUP($D18,records!$A:$V,7,FALSE) -> 73000 | AA18: Redevance 2026 | AB18: =VLOOKUP(O18,'records (2)'!$A:$Z,8,FALSE) -> 30 | AC18: FALSE | AF18: =VLOOKUP($D18,records!$A:$V,13,FALSE) -> PASTACORP TRAITEUR sas | AH18: =VLOOKUP($D18,records!$A:$V,19,FALSE) -> 21 Rue de Borolan | AI18: =VLOOKUP($D18,records!$A:$V,14,FALSE) -> CHAMBERY | AJ18: =VLOOKUP($O18,'records (2)'!$A:$Z,14,FALSE) -> 003IV000010rvHPYAY | AK18: =VLOOKUP($O18,'records (2)'!$A:$Z,15,FALSE) -> Lory LAGACHE (Facturation) | AL18: =VLOOKUP($O18,'records (2)'!$A:$Z,10,FALSE) -> 003IV000010rvHFYAY | AM18: =VLOOKUP($O18,'records (2)'!$A:$Z,11,FALSE) -> Lory LAGACHE | AN18: 1 | AO18: 1000 | AP18: 1000 | AQ18: 0 | AR18: 0
A19: AUTJ-01690 | B19: AUTAJON FRANCE | C19: AUTAJON GROUPE | D19: 001IV000015RhU6YAK | E19: 01tIV00000GyVCbYAN | F19: Redevance d'utilisation - Tranche 25 ETP - Cas 2 | H19: Annual | I19: In advance | J19: 46023 | K19: 46387 | L19: Pixid France | M19: Pack C&S | N19: 46023 | O19: =VLOOKUP(D19,records!$A:$U,10,FALSE) -> 0012p00004MzQWLAA3 | P19: =VLOOKUP(D19,records!$A:$V,20,FALSE) -> FR59538487885 | Q19: =VLOOKUP(D19,records!$A:$V,12,FALSE) -> 34 787 539 500 013 | R19: Paper | T19: Transfer | U19: Renewal | V19: =VLOOKUP($D19,records!$A:$V,3,FALSE) -> AUTAJON SERVICES sasu | X19: =VLOOKUP($D19,records!$A:$V,9,FALSE) -> 36 route d'Espeluche- CS 40149 | Y19: =VLOOKUP($D19,records!$A:$V,4,FALSE) -> MONTELIMAR CEDEX | Z19: =VLOOKUP($D19,records!$A:$V,7,FALSE) -> 26216 | AA19: Redevance 2026 | AB19: =VLOOKUP(O19,'records (2)'!$A:$Z,8,FALSE) -> 30 | AC19: FALSE | AF19: =VLOOKUP($D19,records!$A:$V,13,FALSE) -> AUTAJON SERVICES sasu | AH19: =VLOOKUP($D19,records!$A:$V,19,FALSE) -> 36 route d'Espeluche- CS 40149 | AI19: =VLOOKUP($D19,records!$A:$V,14,FALSE) -> MONTELIMAR CEDEX | AJ19: =VLOOKUP($O19,'records (2)'!$A:$Z,14,FALSE) -> 003IV000010rv3eYAA | AK19: =VLOOKUP($O19,'records (2)'!$A:$Z,15,FALSE) -> Evelyne VICHARD | AL19: =VLOOKUP($O19,'records (2)'!$A:$Z,10,FALSE) -> 003IV000010t2ZTYAY | AM19: =VLOOKUP($O19,'records (2)'!$A:$Z,11,FALSE) -> Michele MOLINA | AN19: 1 | AO19: 9000 | AP19: 9000 | AQ19: 0 | AR19: 0
A20: PIDF-01796 | B20: POINT P IDF | C20: POINT P IDF | D20: 001IV000015RyDxYAK | E20: 01tIV00000GOfP1YAL | F20: Redevance d'utilisation - Tranche 25 ETP - Cas 1 | H20: Annual | I20: In advance | J20: 46023 | K20: 46387 | L20: Pixid France | M20: Pack C&S | N20: 46023 | O20: =VLOOKUP(D20,records!$A:$U,10,FALSE) -> 001SZ000004rtaLYAQ | P20: =VLOOKUP(D20,records!$A:$V,20,FALSE) -> FR73695680108 | Q20: =VLOOKUP(D20,records!$A:$V,12,FALSE) -> 69 568 010 802 753 | R20: Paper | T20: Transfer | U20: Renewal | V20: =VLOOKUP($D20,records!$A:$V,3,FALSE) -> POINT. P S.A.S. | W20: =IFERROR(VLOOKUP($D20,records!$A:$V,6,FALSE),) -> IDF - BCR | X20: =VLOOKUP($D20,records!$A:$V,9,FALSE) -> 9 rue Chappe Gessalin | Y20: =VLOOKUP($D20,records!$A:$V,4,FALSE) -> BRIE COMTE ROBERT | Z20: =VLOOKUP($D20,records!$A:$V,7,FALSE) -> 77170 | AA20: Redevance 2026 | AB20: =VLOOKUP(O20,'records (2)'!$A:$Z,8,FALSE) -> 30 | AC20: FALSE | AF20: =VLOOKUP($D20,records!$A:$V,13,FALSE) -> POINT P IDF | AH20: =VLOOKUP($D20,records!$A:$V,19,FALSE) -> 4 Boulevard Jean Moulin - CS10429 | AI20: =VLOOKUP($D20,records!$A:$V,14,FALSE) -> NANTES | AJ20: =VLOOKUP($O20,'records (2)'!$A:$Z,14,FALSE) -> 003IV000010rlbQYAQ | AK20: =VLOOKUP($O20,'records (2)'!$A:$Z,15,FALSE) -> Clara ARCHER | AL20: =VLOOKUP($O20,'records (2)'!$A:$Z,10,FALSE) -> 003IV000010rlbQYAQ | AM20: =VLOOKUP($O20,'records (2)'!$A:$Z,11,FALSE) -> Clara ARCHER | AN20: 1 | AO20: 1500 | AP20: 1500 | AQ20: 0 | AR20: 0
A21: LSIF-01703 | B21: LIS FRANCE | C21: LIS FRANCE | D21: 001IV000015S8iTYAS | E21: 01tIV00000GOfP1YAL | F21: Redevance d'utilisation - Tranche 25 ETP - Cas 1 | H21: Annual | I21: In advance | J21: 46023 | K21: 46387 | L21: Pixid France | M21: Pack C&S | N21: 46023 | O21: =VLOOKUP(D21,records!$A:$U,10,FALSE) -> 0012p00004UJFBRAA5 | P21: =VLOOKUP(D21,records!$A:$V,20,FALSE) -> FR12692015266 | Q21: =VLOOKUP(D21,records!$A:$V,12,FALSE) -> 69 201 526 600 020 | R21: Paper | T21: Transfer | U21: Renewal | V21: =VLOOKUP($D21,records!$A:$V,3,FALSE) -> LIS France sa | W21: =IFERROR(VLOOKUP($D21,records!$A:$V,6,FALSE),) -> Service RH | X21: =VLOOKUP($D21,records!$A:$V,9,FALSE) -> 67 rue de la Gare | Y21: =VLOOKUP($D21,records!$A:$V,4,FALSE) -> CERENCES | Z21: =VLOOKUP($D21,records!$A:$V,7,FALSE) -> 50510 | AA21: Redevance 2026 | AB21: =VLOOKUP(O21,'records (2)'!$A:$Z,8,FALSE) -> 30 | AC21: FALSE | AF21: =VLOOKUP($D21,records!$A:$V,13,FALSE) -> LIS France sa | AH21: =VLOOKUP($D21,records!$A:$V,19,FALSE) -> 67 rue de la Gare | AI21: =VLOOKUP($D21,records!$A:$V,14,FALSE) -> CERENCES | AJ21: =VLOOKUP($O21,'records (2)'!$A:$Z,14,FALSE) -> 003IV000010sxFvYAI | AK21: =VLOOKUP($O21,'records (2)'!$A:$Z,15,FALSE) -> Franck MORIN | AL21: =VLOOKUP($O21,'records (2)'!$A:$Z,10,FALSE) -> 003IV000010tRVeYAM | AM21: =VLOOKUP($O21,'records (2)'!$A:$Z,11,FALSE) -> Viviane PAWLAK - (compta) | AN21: 1 | AO21: 1000 | AP21: 1000 | AQ21: 0 | AR21: 0
A22: ALMG-01848 | B22: ALMA GROUPE | C22: ALMA GROUPE | D22: 001IV000015RyDjYAK | E22: 01tIV00000GyVCbYAN | F22: Redevance d'utilisation - Tranche 25 ETP - Cas 2 | H22: Annual | I22: In advance | J22: 46023 | K22: 46387 | L22: Pixid France | M22: Pack C&S | N22: 46023 | O22: =VLOOKUP(D22,records!$A:$U,10,FALSE) -> 0012p00004UHPDrAAP | P22: =VLOOKUP(D22,records!$A:$V,20,FALSE) -> FR31304488794 | Q22: =VLOOKUP(D22,records!$A:$V,12,FALSE) -> 30 448 879 400 146 | R22: Paper | T22: Transfer | U22: Renewal | V22: =VLOOKUP($D22,records!$A:$V,3,FALSE) -> ALMA SA | X22: =VLOOKUP($D22,records!$A:$V,9,FALSE) -> 70 Avenue des Sources | Y22: =VLOOKUP($D22,records!$A:$V,4,FALSE) -> SAINT- YORRE | Z22: =VLOOKUP($D22,records!$A:$V,7,FALSE) -> 3270 | AA22: Redevance 2026 | AB22: =VLOOKUP(O22,'records (2)'!$A:$Z,8,FALSE) -> 30 | AC22: FALSE | AF22: =VLOOKUP($D22,records!$A:$V,13,FALSE) -> ALMA SA | AH22: =VLOOKUP($D22,records!$A:$V,19,FALSE) -> 70 Avenue des Sources | AI22: =VLOOKUP($D22,records!$A:$V,14,FALSE) -> SAINT- YORRE | AJ22: =VLOOKUP($O22,'records (2)'!$A:$Z,14,FALSE) -> 003IV000010tJXDYA2 | AK22: =VLOOKUP($O22,'records (2)'!$A:$Z,15,FALSE) -> Olivier GIRAUD | AL22: =VLOOKUP($O22,'records (2)'!$A:$Z,10,FALSE) -> 003IV000010tJXDYA2 | AM22: =VLOOKUP($O22,'records (2)'!$A:$Z,11,FALSE) -> Olivier GIRAUD | AN22: 1 | AO22: 9000 | AP22: 9000 | AQ22: 0 | AR22: 0
A23: SAES-01653 | B23: SENIOR AEROSPACE ERMETO S.A.S | C23: SENIOR | D23: 001IV000015S50LYAS | E23: 01tIV00000GOfP1YAL | F23: Redevance d'utilisation - Tranche 25 ETP - Cas 1 | H23: Annual | I23: In advance | J23: 46023 | K23: 46387 | L23: Pixid France | M23: Pack C&S | N23: 46023 | O23: =VLOOKUP(D23,records!$A:$U,10,FALSE) -> 0012p00004RIoWPAA1 | P23: =VLOOKUP(D23,records!$A:$V,20,FALSE) -> FR37440285401 | Q23: =VLOOKUP(D23,records!$A:$V,12,FALSE) -> 44 028 540 100 053 | R23: Paper | T23: Transfer | U23: Renewal | V23: =VLOOKUP($D23,records!$A:$V,3,FALSE) -> SENIOR AEROSPACE ERMETO SAS | X23: =VLOOKUP($D23,records!$A:$V,9,FALSE) -> 8 rue du Clos Thomas - BP 30 | Y23: =VLOOKUP($D23,records!$A:$V,4,FALSE) -> FOSSÉ | Z23: =VLOOKUP($D23,records!$A:$V,7,FALSE) -> 41330 | AA23: Redevance 2026 | AB23: =VLOOKUP(O23,'records (2)'!$A:$Z,8,FALSE) -> 30 | AC23: FALSE | AF23: =VLOOKUP($D23,records!$A:$V,13,FALSE) -> SENIOR AEROSPACE ERMETO SAS | AH23: =VLOOKUP($D23,records!$A:$V,19,FALSE) -> 8 rue du Clos Thomas - BP 30 | AI23: =VLOOKUP($D23,records!$A:$V,14,FALSE) -> FOSSÉ | AJ23: =VLOOKUP($O23,'records (2)'!$A:$Z,14,FALSE) -> 003IV000010tQI5YAM | AK23: =VLOOKUP($O23,'records (2)'!$A:$Z,15,FALSE) -> Prescillia MORIS | AL23: =VLOOKUP($O23,'records (2)'!$A:$Z,10,FALSE) -> 003IV000010tQI6YAM | AM23: =VLOOKUP($O23,'records (2)'!$A:$Z,11,FALSE) -> Fabienne POTAGE LEGOFF | AN23: 1 | AO23: 1000 | AP23: 1000 | AQ23: 0 | AR23: 0
A24: ELDN-01899 | B24: ELYDAN SAS | C24: ELYDAN sas | D24: 001IV000015SAI9YAO | E24: 01tIV00000GyVCbYAN | F24: Redevance d'utilisation - Tranche 25 ETP - Cas 2 | H24: Annual | I24: In advance | J24: 46023 | K24: 46387 | L24: Pixid France | M24: Pack C&S | N24: 46023 | O24: =VLOOKUP(D24,records!$A:$U,10,FALSE) -> 001SZ000007iWoDYAU | P24: =VLOOKUP(D24,records!$A:$V,20,FALSE) -> FR26388062796 | Q24: =VLOOKUP(D24,records!$A:$V,12,FALSE) -> 38 806 279 600 080 | R24: Email | S24: =VLOOKUP(D24,records!$A:$W,19,FALSE) -> acano@elydan.eu | T24: Transfer | U24: Renewal | V24: =VLOOKUP($D24,records!$A:$V,3,FALSE) -> ELYDAN sas | W24: =IFERROR(VLOOKUP($D24,records!$A:$V,6,FALSE),) -> Ressources Humaines | X24: =VLOOKUP($D24,records!$A:$V,9,FALSE) -> 127 Avenue Louis Bleriot | Y24: =VLOOKUP($D24,records!$A:$V,4,FALSE) -> SAINT ETIENNE DE SAINT GEOIRS | Z24: =VLOOKUP($D24,records!$A:$V,7,FALSE) -> 38590 | AA24: Redevance 2026 | AB24: =VLOOKUP(O24,'records (2)'!$A:$Z,8,FALSE) -> 30 | AC24: FALSE | AF24: =VLOOKUP($D24,records!$A:$V,13,FALSE) -> ELYDAN sas | AG24: Facture originale électronique à | AH24: =VLOOKUP($D24,records!$A:$V,19,FALSE) -> acano@elydan.eu | AI24: =VLOOKUP($D24,records!$A:$V,14,FALSE) -> . | AJ24: =VLOOKUP($O24,'records (2)'!$A:$Z,14,FALSE) -> 003IV000010sqLJYAY | AK24: =VLOOKUP($O24,'records (2)'!$A:$Z,15,FALSE) -> Facture Elydan | AL24: =VLOOKUP($O24,'records (2)'!$A:$Z,10,FALSE) -> 003IV000010sqLKYAY | AM24: =VLOOKUP($O24,'records (2)'!$A:$Z,11,FALSE) -> Relance Factures Elydan | AN24: 1 | AO24: 3000 | AP24: 3000 | AQ24: 0 | AR24: 0
A25: RVMA-01671 | B25: REVIMA | C25: REVIMA | D25: 001IV000015RyL0YAK | E25: 01tIV00000GOfP6YAL | F25: Redevance d'utilisation - ETP EU | H25: Annual | I25: In advance | J25: 46023 | K25: 46387 | L25: Pixid France | M25: Pack C&S | N25: 46023 | O25: =VLOOKUP(D25,records!$A:$U,10,FALSE) -> 0012p00004THFNVAA5 | P25: =VLOOKUP(D25,records!$A:$V,20,FALSE) -> FR75542071329 | Q25: =VLOOKUP(D25,records!$A:$V,12,FALSE) -> 54 207 132 900 024 | R25: Email | S25: =VLOOKUP(D25,records!$A:$W,19,FALSE) -> account.payable@revima.fr | T25: Transfer | U25: Renewal | V25: =VLOOKUP($D25,records!$A:$V,3,FALSE) -> REVIMA sasu | X25: =VLOOKUP($D25,records!$A:$V,9,FALSE) -> 1 Avenue du Latham 47 | Y25: =VLOOKUP($D25,records!$A:$V,4,FALSE) -> RIVES-EN-SEINE | Z25: =VLOOKUP($D25,records!$A:$V,7,FALSE) -> 76490 | AA25: Redevance 2026 | AB25: =VLOOKUP(O25,'records (2)'!$A:$Z,8,FALSE) -> 30 | AC25: FALSE | AF25: =VLOOKUP($D25,records!$A:$V,13,FALSE) -> REVIMA sasu | AG25: Facture originale électronique à | AH25: =VLOOKUP($D25,records!$A:$V,19,FALSE) -> account.payable@revima.fr | AI25: =VLOOKUP($D25,records!$A:$V,14,FALSE) -> . | AJ25: =VLOOKUP($O25,'records (2)'!$A:$Z,14,FALSE) -> 003IV000010tIiXYAU | AK25: =VLOOKUP($O25,'records (2)'!$A:$Z,15,FALSE) -> Facturation REVIMA | AL25: =VLOOKUP($O25,'records (2)'!$A:$Z,10,FALSE) -> 003IV000010tIiXYAU | AM25: =VLOOKUP($O25,'records (2)'!$A:$Z,11,FALSE) -> Facturation REVIMA | AN25: 1 | AO25: 2000 | AP25: 2000 | AQ25: 0 | AR25: 0
A26: MMGS-01617 | B26: MILLET MOUNTAIN GROUP | C26: MILLET MOUNTAIN GROUP SAS | D26: 001IV000015S50KYAS | E26: 01tIV00000GOfP1YAL | F26: Redevance d'utilisation - Tranche 25 ETP - Cas 1 | H26: Annual | I26: In advance | J26: 46023 | K26: 46387 | L26: Pixid France | M26: Pack C&S | N26: 46023 | O26: =VLOOKUP(D26,records!$A:$U,10,FALSE) -> 0012p00004RDYqlAAH | P26: =VLOOKUP(D26,records!$A:$V,20,FALSE) -> FR38400313318 | Q26: =VLOOKUP(D26,records!$A:$V,12,FALSE) -> 40 031 331 800 026 | R26: Email | S26: =VLOOKUP(D26,records!$A:$U,19,FALSE) -> accounting.millet@milletmountaingroup.com | T26: Transfer | U26: Renewal | V26: =VLOOKUP($D26,records!$A:$V,3,FALSE) -> MILLET MOUNTAIN GROUP SAS | X26: =VLOOKUP($D26,records!$A:$V,9,FALSE) -> 21 rue du Pré Faucon | Y26: =VLOOKUP($D26,records!$A:$V,4,FALSE) -> ANNECY LE VIEUX CEDEX | Z26: =VLOOKUP($D26,records!$A:$V,7,FALSE) -> 74943 | AA26: Redevance 2026 | AB26: =VLOOKUP(O26,'records (2)'!$A:$Z,8,FALSE) -> 30 | AC26: FALSE | AF26: =VLOOKUP($D26,records!$A:$V,13,FALSE) -> MILLET MOUNTAIN GROUP SAS | AG26: Facture originale électronique à | AH26: =VLOOKUP($D26,records!$A:$V,19,FALSE) -> accounting.millet@milletmountaingroup.com | AI26: =VLOOKUP($D26,records!$A:$V,14,FALSE) -> . | AJ26: =VLOOKUP($O26,'records (2)'!$A:$Z,14,FALSE) -> 003IV000010tQIMYA2 | AK26: =VLOOKUP($O26,'records (2)'!$A:$Z,15,FALSE) -> Olivier LENESTOUR (accounting) | AL26: =VLOOKUP($O26,'records (2)'!$A:$Z,10,FALSE) -> 003IV000010tQIMYA2 | AM26: =VLOOKUP($O26,'records (2)'!$A:$Z,11,FALSE) -> Olivier LENESTOUR (accounting) | AN26: 1 | AO26: 500 | AP26: 500 | AQ26: 0 | AR26: 0
A27: AFCB-01660 | B27: AMPHENOL FCI BESANCON | C27: AMPHENOL FCI | D27: 001IV000015SAHqYAO | E27: 01tIV00000GOfP1YAL | F27: Redevance d'utilisation - Tranche 25 ETP - Cas 1 | H27: Annual | I27: In advance | J27: 46023 | K27: 46387 | L27: Pixid France | M27: Pack C&S | N27: 46023 | O27: =VLOOKUP(D27,records!$A:$U,10,FALSE) -> 0012p00004ReLR9AAN | P27: =VLOOKUP(D27,records!$A:$V,20,FALSE) -> FR91388636896 | Q27: =VLOOKUP(D27,records!$A:$V,12,FALSE) -> 38 863 689 600 010 | R27: Email | S27: =VLOOKUP(D27,records!$A:$U,19,FALSE) -> accounts-payable.besancon@fci.com | T27: Transfer | U27: Renewal | V27: =VLOOKUP($D27,records!$A:$V,3,FALSE) -> AMPHENOL FCI BESANCON sas | X27: =VLOOKUP($D27,records!$A:$V,9,FALSE) -> 2 Rue Lafayette | Y27: =VLOOKUP($D27,records!$A:$V,4,FALSE) -> BESANCON | Z27: =VLOOKUP($D27,records!$A:$V,7,FALSE) -> 25000 | AA27: Redevance 2026 | AB27: =VLOOKUP(O27,'records (2)'!$A:$Z,8,FALSE) -> 30 | AC27: FALSE | AF27: =VLOOKUP($D27,records!$A:$V,13,FALSE) -> AMPHENOL FCI BESANCON sas | AG27: Facture originale électronique à | AH27: =VLOOKUP($D27,records!$A:$V,19,FALSE) -> accounts-payable.besancon@fci.com | AI27: =VLOOKUP($D27,records!$A:$V,14,FALSE) -> . | AJ27: =VLOOKUP($O27,'records (2)'!$A:$Z,14,FALSE) -> 003IV000010t1XAYAY | AK27: =VLOOKUP($O27,'records (2)'!$A:$Z,15,FALSE) -> Jemil ISHAK-BOUSHAKI | AL27: =VLOOKUP($O27,'records (2)'!$A:$Z,10,FALSE) -> 003IV000010t1XAYAY | AM27: =VLOOKUP($O27,'records (2)'!$A:$Z,11,FALSE) -> Jemil ISHAK-BOUSHAKI | AN27: 1 | AO27: 1000 | AP27: 1000 | AQ27: 0 | AR27: 0
A28: TAFS-01646 | B28: TENNECO AUTOMOTIVE | C28: TENNECO AUTOMOTIVE FRANCE SAS | D28: 001IV000015RyDiYAK | E28: 01tIV00000GOfP1YAL | F28: Redevance d'utilisation - Tranche 25 ETP - Cas 1 | H28: Annual | I28: In advance | J28: 46023 | K28: 46387 | L28: Pixid France | M28: Pack C&S | N28: 46023 | O28: =VLOOKUP(D28,records!$A:$U,10,FALSE) -> 0012p00004TGrjrAAD | P28: =VLOOKUP(D28,records!$A:$V,20,FALSE) -> FR29555450071 | Q28: =VLOOKUP(D28,records!$A:$V,12,FALSE) -> 55 545 007 100 041 | R28: Email | S28: =VLOOKUP(D28,records!$A:$U,19,FALSE) -> AccountsPayableFrance@Tenneco.com | T28: Transfer | U28: Renewal | V28: =VLOOKUP($D28,records!$A:$V,3,FALSE) -> TENNECO AUTOMOTIVE FRANCE SAS | X28: =VLOOKUP($D28,records!$A:$V,9,FALSE) -> ZA des Giraumeries | Y28: =VLOOKUP($D28,records!$A:$V,4,FALSE) -> SAINT BERTHEVIN | Z28: =VLOOKUP($D28,records!$A:$V,7,FALSE) -> 53940 | AA28: Redevance 2026 | AB28: =VLOOKUP(O28,'records (2)'!$A:$Z,8,FALSE) -> 30 | AC28: FALSE | AF28: =VLOOKUP($D28,records!$A:$V,13,FALSE) -> TENNECO AUTOMOTIVE FRANCE SAS | AG28: Facture originale électronique à | AH28: =VLOOKUP($D28,records!$A:$V,19,FALSE) -> AccountsPayableFrance@Tenneco.com | AI28: =VLOOKUP($D28,records!$A:$V,14,FALSE) -> . | AJ28: =VLOOKUP($O28,'records (2)'!$A:$Z,14,FALSE) -> 003IV000010tJXCYA2 | AK28: =VLOOKUP($O28,'records (2)'!$A:$Z,15,FALSE) -> Sandrine LEVECQUE | AL28: =VLOOKUP($O28,'records (2)'!$A:$Z,10,FALSE) -> 003IV000010tJXCYA2 | AM28: =VLOOKUP($O28,'records (2)'!$A:$Z,11,FALSE) -> Sandrine LEVECQUE | AN28: 1 | AO28: 500 | AP28: 500 | AQ28: 0 | AR28: 0
A29: EXCV-01801 | B29: EXCELVISION | C29: EXCELVISION | D29: 001IV000015S2SQYA0 | E29: 01tIV00000GOfP1YAL | F29: Redevance d'utilisation - Tranche 25 ETP - Cas 1 | H29: Annual | I29: In advance | J29: 46023 | K29: 46387 | L29: Pixid France | M29: Pack C&S | N29: 46023 | O29: =VLOOKUP(D29,records!$A:$U,10,FALSE) -> 0012p00004UJG6aAAH | P29: =VLOOKUP(D29,records!$A:$V,20,FALSE) -> FR82335820684 | Q29: =VLOOKUP(D29,records!$A:$V,12,FALSE) -> 33 582 068 400 033 | R29: Email | S29: =VLOOKUP(D29,records!$A:$U,19,FALSE) -> accueilfactures.excelvision@fareva.com | T29: Transfer | U29: Renewal | V29: =VLOOKUP($D29,records!$A:$V,3,FALSE) -> EXCELVISION sas | X29: =VLOOKUP($D29,records!$A:$V,9,FALSE) -> 27 Rue de la Lombardière | Y29: =VLOOKUP($D29,records!$A:$V,4,FALSE) -> ANNONAY | Z29: =VLOOKUP($D29,records!$A:$V,7,FALSE) -> 7100 | AA29: Redevance 2026 | AB29: =VLOOKUP(O29,'records (2)'!$A:$Z,8,FALSE) -> 60 | AC29: FALSE | AF29: =VLOOKUP($D29,records!$A:$V,13,FALSE) -> EXCELVISION sas | AG29: Facture originale électronique à | AH29: =VLOOKUP($D29,records!$A:$V,19,FALSE) -> accueilfactures.excelvision@fareva.com | AI29: =VLOOKUP($D29,records!$A:$V,14,FALSE) -> . | AJ29: =VLOOKUP($O29,'records (2)'!$A:$Z,14,FALSE) -> 003IV000010t687YAA | AK29: =VLOOKUP($O29,'records (2)'!$A:$Z,15,FALSE) -> Service Comptabilité | AL29: =VLOOKUP($O29,'records (2)'!$A:$Z,10,FALSE) -> 003IV000010t688YAA | AM29: =VLOOKUP($O29,'records (2)'!$A:$Z,11,FALSE) -> Frédéric DE ROMELIN | AN29: 1 | AO29: 500 | AP29: 500 | AQ29: 0 | AR29: 0
A30: LLMD-01802 | B30: SOCIETE LALLEMAND | C30: CALIDA GROUP (LALLEMAND) | D30: 001IV000015RyDzYAK | E30: 01tIV00000GOfP1YAL | F30: Redevance d'utilisation - Tranche 25 ETP - Cas 1 | H30: Annual | I30: In advance | J30: 46023 | K30: 46387 | L30: Pixid France | M30: Pack C&S | N30: 46023 | O30: =VLOOKUP(D30,records!$A:$U,10,FALSE) -> 001SZ000005Od72YAC | P30: =VLOOKUP(D30,records!$A:$V,20,FALSE) -> FR44773201108 | Q30: =VLOOKUP(D30,records!$A:$V,12,FALSE) -> 77 320 110 800 018 | R30: Email | S30: =VLOOKUP(D30,records!$A:$U,19,FALSE) -> adminlallemand@lafuma-mobilier.fr | T30: Transfer | U30: Renewal | V30: =VLOOKUP($D30,records!$A:$V,3,FALSE) -> LALLEMAND SAS | X30: =VLOOKUP($D30,records!$A:$V,9,FALSE) -> Le Balmay | Y30: =VLOOKUP($D30,records!$A:$V,4,FALSE) -> VIEU D'IZENAVE | Z30: =VLOOKUP($D30,records!$A:$V,7,FALSE) -> 1430 | AA30: Redevance 2026 | AB30: =VLOOKUP(O30,'records (2)'!$A:$Z,8,FALSE) -> 30 | AC30: FALSE | AF30: =VLOOKUP($D30,records!$A:$V,13,FALSE) -> LALLEMAND SAS | AG30: Facture originale électronique à | AH30: =VLOOKUP($D30,records!$A:$V,19,FALSE) -> adminlallemand@lafuma-mobilier.fr | AI30: =VLOOKUP($D30,records!$A:$V,14,FALSE) -> . | AJ30: =VLOOKUP($O30,'records (2)'!$A:$Z,14,FALSE) -> 003IV000010su8mYAA | AK30: =VLOOKUP($O30,'records (2)'!$A:$Z,15,FALSE) -> Fabrice CORMORECHE | AL30: =VLOOKUP($O30,'records (2)'!$A:$Z,10,FALSE) -> 003IV000010su8mYAA | AM30: =VLOOKUP($O30,'records (2)'!$A:$Z,11,FALSE) -> Fabrice CORMORECHE | AN30: 1 | AO30: 500 | AP30: 500
A31: KSBS-01588 | B31: KSB | C31: KSB CHATEAUROUX | D31: 001IV000015S85hYAC | E31: 01tIV00000GOfP1YAL | F31: Redevance d'utilisation - Tranche 25 ETP - Cas 1 | H31: Annual | I31: In advance | J31: 46023 | K31: 46387 | L31: Pixid France | M31: Pack C&S | N31: 46023 | O31: =VLOOKUP(D31,records!$A:$U,10,FALSE) -> 0012p00004RmixTAAR | P31: =VLOOKUP(D31,records!$A:$V,20,FALSE) -> FR20569801897 | Q31: =VLOOKUP(D31,records!$A:$V,12,FALSE) -> 56 980 189 700 103 | R31: Email | S31: =VLOOKUP(D31,records!$A:$U,19,FALSE) -> alexandra.rongy@ksb.com | T31: Transfer | U31: Renewal | V31: =VLOOKUP($D31,records!$A:$V,3,FALSE) -> KSB SAS | X31: =VLOOKUP($D31,records!$A:$V,9,FALSE) -> Allée de Sagan | Y31: =VLOOKUP($D31,records!$A:$V,4,FALSE) -> CHATEAUROUX | Z31: =VLOOKUP($D31,records!$A:$V,7,FALSE) -> 36000 | AA31: Redevance 2026 | AB31: =VLOOKUP(O31,'records (2)'!$A:$Z,8,FALSE) -> 30 | AC31: FALSE | AF31: =VLOOKUP($D31,records!$A:$V,13,FALSE) -> KSB SAS | AG31: Facture originale électronique à | AH31: =VLOOKUP($D31,records!$A:$V,19,FALSE) -> alexandra.rongy@ksb.com | AI31: =VLOOKUP($D31,records!$A:$V,14,FALSE) -> . | AJ31: =VLOOKUP($O31,'records (2)'!$A:$Z,14,FALSE) -> 003IV000010tIdmYAE | AK31: =VLOOKUP($O31,'records (2)'!$A:$Z,15,FALSE) -> Thomas BRUNEAU | AL31: =VLOOKUP($O31,'records (2)'!$A:$Z,10,FALSE) -> 003IV000010sxGoYAI | AM31: =VLOOKUP($O31,'records (2)'!$A:$Z,11,FALSE) -> Fabienne BOISBOURDIN | AN31: 1 | AO31: 500 | AP31: 500 | AQ31: 0 | AR31: 0
A32: PRMS-01766 | B32: BERRY BEAUTE MAROLLES | C32: BERRY GLOBAL - PROMENS - (EX PGI) | D32: 001IV000015S867YAC | E32: 01tIV00000GOfP1YAL | F32: Redevance d'utilisation - Tranche 25 ETP - Cas 1 | G32: BERRY BEAUTE MAROLLES | H32: Annual | I32: In advance | J32: 46023 | K32: 46387 | L32: Pixid France | M32: Pack C&S | N32: 46023 | O32: =VLOOKUP(D32,records!$A:$U,10,FALSE) -> 001SZ000003ZJXVYA4 | P32: =VLOOKUP(D32,records!$A:$V,20,FALSE) -> FR52759200454 | Q32: =VLOOKUP(D32,records!$A:$V,12,FALSE) -> 75 920 045 400 156 | R32: Email | S32: alexandragrossat@berryglobal.com | T32: Transfer | U32: Renewal | V32: =VLOOKUP($D32,records!$A:$V,3,FALSE) -> PROMENS SA | X32: =VLOOKUP($D32,records!$A:$V,9,FALSE) -> 5 Rue Castellion | Y32: =VLOOKUP($D32,records!$A:$V,4,FALSE) -> BELLIGNAT | Z32: 01100 | AA32: Redevance 2026 | AB32: =VLOOKUP(O32,'records (2)'!$A:$Z,8,FALSE) -> 30 | AC32: =VLOOKUP(O32,'records (4)'!$A:$C,3,FALSE) -> TRUE | AD32: YES | AE32: 46023 | AF32: =VLOOKUP($D32,records!$A:$V,13,FALSE) -> PROMENS SA | AG32: Facture originale électronique à | AH32: alexandragrossat@berryglobal.com | AI32: =VLOOKUP($D32,records!$A:$V,14,FALSE) -> . | AJ32: =VLOOKUP($O32,'records (2)'!$A:$Z,14,FALSE) -> 003IV000010su8aYAA | AK32: =VLOOKUP($O32,'records (2)'!$A:$Z,15,FALSE) -> Alexandra GROSSAT | AL32: =VLOOKUP($O32,'records (2)'!$A:$Z,10,FALSE) -> 003IV000010su8aYAA | AM32: =VLOOKUP($O32,'records (2)'!$A:$Z,11,FALSE) -> Alexandra GROSSAT | AN32: 1 | AO32: 1500 | AP32: 1500 | AQ32: 0 | AR32: 0
A33: Pas de code facture | B33: BERRY BRAMLAGE | C33: BERRY BRAMLAGE | D33: 001IV000015S867YAC | E33: 01tIV00000GOfP1YAL | F33: Redevance d'utilisation - Tranche 25 ETP - Cas 1 | G33: BERRY BRAMLAGE | H33: Annual | I33: In advance | J33: 46023 | K33: 46387 | L33: Pixid France | M33: Pack C&S | N33: 46023 | O33: =VLOOKUP(D33,records!$A:$U,10,FALSE) -> 001SZ000003ZJXVYA4 | P33: FR52759200454 | Q33: 75920045400156 | R33: Email | S33: alexandragrossat@berryglobal.com | T33: Transfer | U33: Renewal | V33: PROMENS SA | X33: 5 Rue Castellion | Y33: BELLIGNAT | Z33: 01100 | AA33: Redevance 2026 | AB33: =VLOOKUP(O33,'records (2)'!$A:$Z,8,FALSE) -> 30 | AC33: =VLOOKUP(O33,'records (4)'!$A:$C,3,FALSE) -> TRUE | AD33: YES | AE33: 46023 | AF33: PROMENS SA | AG33: Facture originale électronique à | AH33: alexandragrossat@berryglobal.com | AI33: . | AJ33: 003IV000010su8aYAA | AK33: Alexandra GROSSAT | AL33: 003IV000010su8aYAA | AM33: Alexandra GROSSAT | AN33: 1 | AO33: 1000 | AP33: 1000 | AQ33: 0 | AR33: Redevance pas facturé en 2025
A34: DFOS-01629 | B34: DANFOSS | C34: DANFOSS | D34: 001IV000015S50OYAS | E34: 01tIV00000GOfP1YAL | F34: Redevance d'utilisation - Tranche 25 ETP - Cas 1 | H34: Annual | I34: In advance | J34: 46023 | K34: 46387 | L34: Pixid France | M34: Pack C&S | N34: 46023 | O34: =VLOOKUP(D34,records!$A:$U,10,FALSE) -> 0012p00004SxGjuAAF | P34: =VLOOKUP(D34,records!$A:$V,20,FALSE) -> FR80713780278 | Q34: =VLOOKUP(D34,records!$A:$V,12,FALSE) -> 71 378 027 800 030 | R34: Email | S34: =VLOOKUP(D34,records!$A:$U,19,FALSE) -> amelie.chesneau@danfoss.com | T34: Transfer | U34: Renewal | V34: =VLOOKUP($D34,records!$A:$V,3,FALSE) -> DANFOSS COMMERCIAL COMPRESSORS sa | W34: =IFERROR(VLOOKUP($D34,records!$A:$V,6,FALSE),) -> Comptabilité | X34: =VLOOKUP($D34,records!$A:$V,9,FALSE) -> ZI de Reyrieux - BP331 | Y34: =VLOOKUP($D34,records!$A:$V,4,FALSE) -> TREVOUX | Z34: =VLOOKUP($D34,records!$A:$V,7,FALSE) -> 1600 | AA34: Redevance 2026 | AB34: =VLOOKUP(O34,'records (2)'!$A:$Z,8,FALSE) -> 45 | AC34: =VLOOKUP(O34,'records (4)'!$A:$C,3,FALSE) -> TRUE | AD34: YES | AE34: 46023 | AF34: =VLOOKUP($D34,records!$A:$V,13,FALSE) -> DANFOSS COMMERCIAL COMPRESSORS sa | AG34: Facture originale électronique à | AH34: =VLOOKUP($D34,records!$A:$V,19,FALSE) -> amelie.chesneau@danfoss.com | AI34: . | AJ34: =VLOOKUP($O34,'records (2)'!$A:$Z,14,FALSE) -> 003IV000010t7J0YAI | AK34: =VLOOKUP($O34,'records (2)'!$A:$Z,15,FALSE) -> Sylvie BERTOIN | AL34: =VLOOKUP($O34,'records (2)'!$A:$Z,10,FALSE) -> 003IV000010tIiJYAU | AM34: =VLOOKUP($O34,'records (2)'!$A:$Z,11,FALSE) -> Corinne ROCHA | AN34: 1 | AO34: 2000 | AP34: 2000 | AQ34: 0 | AR34: 0
A35: FRCS-01805 | B35: SISLEY INDUSTRIE | C35: FRANCOS - (SISLEY) | D35: 001IV000015RyDwYAK | E35: 01tIV00000GyVCbYAN | F35: Redevance d'utilisation - Tranche 25 ETP - Cas 2 | H35: Annual | I35: In advance | J35: 46023 | K35: 46387 | L35: Pixid France | M35: Pack C&S | N35: 46023 | O35: =VLOOKUP(D35,records!$A:$U,10,FALSE) -> 001SZ000004b5HnYAI | P35: =VLOOKUP(D35,records!$A:$V,20,FALSE) -> FR62450982343 | Q35: =VLOOKUP(D35,records!$A:$V,12,FALSE) -> 45 098 234 300 011 | R35: Email | S35: =VLOOKUP(D35,records!$A:$U,19,FALSE) -> amelie.rousselot@francos.fr | T35: Transfer | U35: Renewal | V35: =VLOOKUP($D35,records!$A:$V,3,FALSE) -> FRANCOS sasu | X35: =VLOOKUP($D35,records!$A:$V,9,FALSE) -> 1 Rue des Mardeaux | Y35: =VLOOKUP($D35,records!$A:$V,4,FALSE) -> BLOIS | Z35: =VLOOKUP($D35,records!$A:$V,7,FALSE) -> 41000 | AA35: Redevance 2026 | AB35: =VLOOKUP(O35,'records (2)'!$A:$Z,8,FALSE) -> 30 | AC35: FALSE | AF35: =VLOOKUP($D35,records!$A:$V,13,FALSE) -> FRANCOS sasu | AG35: Facture originale électronique à | AH35: =VLOOKUP($D35,records!$A:$V,19,FALSE) -> amelie.rousselot@francos.fr | AI35: . | AJ35: =VLOOKUP($O35,'records (2)'!$A:$Z,14,FALSE) -> 003IV000010t2BcYAI | AK35: =VLOOKUP($O35,'records (2)'!$A:$Z,15,FALSE) -> Amelie ROUSSELOT | AL35: =VLOOKUP($O35,'records (2)'!$A:$Z,10,FALSE) -> 003IV000010t2BcYAI | AM35: =VLOOKUP($O35,'records (2)'!$A:$Z,11,FALSE) -> Amelie ROUSSELOT | AN35: 1 | AO35: 1000 | AP35: 1000 | AQ35: 0 | AR35: 0
A36: VSTP-01868 | B36: VOESTALPINE | C36: VOESTALPINE | D36: 001IV000015S2eKYAS | E36: 01tIV00000GOfP1YAL | F36: Redevance d'utilisation - Tranche 25 ETP - Cas 1 | H36: Annual | I36: In advance | J36: 46023 | K36: 46387 | L36: Pixid France | M36: Pack C&S | N36: 46023 | O36: =VLOOKUP(D36,records!$A:$U,10,FALSE) -> 001SZ000001pKNXYA2 | P36: =VLOOKUP(D36,records!$A:$V,20,FALSE) -> FR12535520316 | Q36: =VLOOKUP(D36,records!$A:$V,12,FALSE) -> 53 552 031 600 014 | R36: Email | S36: =VLOOKUP(D36,records!$A:$U,19,FALSE) -> andrea.cametti@voestalpine.com | T36: Transfer | U36: Renewal | V36: =VLOOKUP($D36,records!$A:$V,3,FALSE) -> VOESTALPINE AUTOMOTIVE COMPONENTS FONTAINE sa | X36: =VLOOKUP($D36,records!$A:$V,9,FALSE) -> Zac de l'Aéroparc | Y36: =VLOOKUP($D36,records!$A:$V,4,FALSE) -> FONTAINE | Z36: =VLOOKUP($D36,records!$A:$V,7,FALSE) -> 90150 | AA36: Redevance 2026 | AB36: =VLOOKUP(O36,'records (2)'!$A:$Z,8,FALSE) -> 30 | AC36: FALSE | AF36: =VLOOKUP($D36,records!$A:$V,13,FALSE) -> VOESTALPINE AUTOMOTIVE COMPONENTS FONTAINE sa | AG36: Facture originale électronique à | AH36: =VLOOKUP($D36,records!$A:$V,19,FALSE) -> andrea.cametti@voestalpine.com | AI36: . | AJ36: =VLOOKUP($O36,'records (2)'!$A:$Z,14,FALSE) -> 003IV000010su9YYAQ | AK36: =VLOOKUP($O36,'records (2)'!$A:$Z,15,FALSE) -> Christine BONTEMPS | AL36: =VLOOKUP($O36,'records (2)'!$A:$Z,10,FALSE) -> 003IV000010su9YYAQ | AM36: =VLOOKUP($O36,'records (2)'!$A:$Z,11,FALSE) -> Christine BONTEMPS | AN36: 1 | AO36: 500 | AP36: 500 | AQ36: 0 | AR36: 0
A37: LBSP-01837 | B37: BIO SPRINGER | C37: LESAFFRE - BIO SPRINGER | D37: 001IV000015S8j3YAC | E37: 01tIV00000GyVCbYAN | F37: Redevance d'utilisation - Tranche 25 ETP - Cas 2 | H37: Annual | I37: In advance | J37: 46023 | K37: 46387 | L37: Pixid France | M37: Pack C&S | N37: 46023 | O37: =VLOOKUP(D37,records!$A:$U,10,FALSE) -> 001SZ000003YcdpYAC | P37: =VLOOKUP(D37,records!$A:$V,20,FALSE) -> FR93542091996 | Q37: =VLOOKUP(D37,records!$A:$V,12,FALSE) -> 54 209 199 600 026 | R37: Email | S37: =VLOOKUP(D37,records!$A:$U,19,FALSE) -> ap.biospringer@lesaffre.com | T37: Transfer | U37: Renewal | V37: =VLOOKUP($D37,records!$A:$V,3,FALSE) -> BIO SPRINGER sa | W37: =IFERROR(VLOOKUP($D37,records!$A:$V,6,FALSE),) -> Ressources Humaines | X37: =VLOOKUP($D37,records!$A:$V,9,FALSE) -> 103 Rue Jean Jaurès | Y37: =VLOOKUP($D37,records!$A:$V,4,FALSE) -> MAISONS-ALFORT | Z37: =VLOOKUP($D37,records!$A:$V,7,FALSE) -> 94700 | AA37: Redevance 2026 | AB37: =VLOOKUP(O37,'records (2)'!$A:$Z,8,FALSE) -> 60 | AC37: =VLOOKUP(O37,'records (4)'!$A:$C,3,FALSE) -> TRUE | AD37: YES | AE37: 46023 | AF37: =VLOOKUP($D37,records!$A:$V,13,FALSE) -> BIO SPRINGER sa | AG37: Facture originale électronique à | AH37: =VLOOKUP($D37,records!$A:$V,19,FALSE) -> ap.biospringer@lesaffre.com | AI37: . | AJ37: =VLOOKUP($O37,'records (2)'!$A:$Z,14,FALSE) -> 003IV000010tSnLYAU | AK37: =VLOOKUP($O37,'records (2)'!$A:$Z,15,FALSE) -> Morgane PEREZ | AL37: =VLOOKUP($O37,'records (2)'!$A:$Z,10,FALSE) -> 003IV000010sqM3YAI | AM37: =VLOOKUP($O37,'records (2)'!$A:$Z,11,FALSE) -> Contact Recouvrement LESAFFRE - BIO SPRINGER | AN37: 1 | AO37: 2000 | AP37: 2000 | AQ37: 0 | AR37: 0
A38: NMRV-01867 | B38: NEMERA SERVICES | C38: NEMERA | D38: 001IV000015S8jFYAS | E38: 01tIV00000GOfP1YAL | F38: Redevance d'utilisation - Tranche 25 ETP - Cas 1 | H38: Annual | I38: In advance | J38: 46023 | K38: 46387 | L38: Pixid France | M38: Pack C&S | N38: 46023 | O38: =VLOOKUP(D38,records!$A:$U,10,FALSE) -> 001SZ00000BFAySYAX | P38: =VLOOKUP(D38,records!$A:$V,20,FALSE) -> FR81388056962 | Q38: =VLOOKUP(D38,records!$A:$V,12,FALSE) -> 38 805 696 200 029 | R38: Email | S38: =VLOOKUP(D38,records!$A:$U,19,FALSE) -> ap.invoicesnemeralaverpilliere@nemera.net | T38: Transfer | U38: Renewal | V38: =VLOOKUP($D38,records!$A:$V,3,FALSE) -> NEMERA LA VERPILIERE sas | X38: =VLOOKUP($D38,records!$A:$V,9,FALSE) -> 20 Avenue de la Gare | Y38: =VLOOKUP($D38,records!$A:$V,4,FALSE) -> LA VERPILLIERE | Z38: =VLOOKUP($D38,records!$A:$V,7,FALSE) -> 38290 | AA38: Redevance 2026 | AB38: =VLOOKUP(O38,'records (2)'!$A:$Z,8,FALSE) -> 30 | AC38: =VLOOKUP(O38,'records (4)'!$A:$C,3,FALSE) -> TRUE | AD38: YES | AE38: 46023 | AF38: =VLOOKUP($D38,records!$A:$V,13,FALSE) -> NEMERA LA VERPILIERE sas | AG38: Facture originale électronique à | AH38: =VLOOKUP($D38,records!$A:$V,19,FALSE) -> ap.invoicesnemeralaverpilliere@nemera.net | AI38: . | AJ38: =VLOOKUP($O38,'records (2)'!$A:$Z,14,FALSE) -> 003IV000010su9XYAQ | AK38: =VLOOKUP($O38,'records (2)'!$A:$Z,15,FALSE) -> Laurence DALLEMAGNE | AL38: =VLOOKUP($O38,'records (2)'!$A:$Z,10,FALSE) -> 003IV000010su9XYAQ | AM38: =VLOOKUP($O38,'records (2)'!$A:$Z,11,FALSE) -> Laurence DALLEMAGNE | AN38: 1 | AO38: 2000 | AP38: 2000 | AQ38: 0 | AR38: 0
A39: KSBR-01791 | B39: KSB LA ROCHE CHALAIS | C39: KSB LA ROCHE CHALAIS | D39: 001IV000015S862YAC | E39: 01tIV00000GOfP1YAL | F39: Redevance d'utilisation - Tranche 25 ETP - Cas 1 | H39: Annual | I39: In advance | J39: 46023 | K39: 46387 | L39: Pixid France | M39: Pack C&S | N39: 46023 | O39: =VLOOKUP(D39,records!$A:$U,10,FALSE) -> 0012p00004UIt7LAAT | P39: =VLOOKUP(D39,records!$A:$V,20,FALSE) -> FR20569801897 | Q39: =VLOOKUP(D39,records!$A:$V,12,FALSE) -> 56 980 189 700 632 | R39: Email | S39: =VLOOKUP(D39,records!$A:$U,19,FALSE) -> ap_invoices_fr@ksb.com | T39: Transfer | U39: Renewal | V39: =VLOOKUP($D39,records!$A:$V,3,FALSE) -> KSB SAS | W39: =IFERROR(VLOOKUP($D39,records!$A:$V,6,FALSE),) -> Comptabilité fournisseurs | X39: =VLOOKUP($D39,records!$A:$V,9,FALSE) -> 4 Allée des Barbanniers | Y39: =VLOOKUP($D39,records!$A:$V,4,FALSE) -> GENNEVILLIERS | Z39: =VLOOKUP($D39,records!$A:$V,7,FALSE) -> 92230 | AA39: Redevance 2026 | AB39: =VLOOKUP(O39,'records (2)'!$A:$Z,8,FALSE) -> 30 | AC39: FALSE | AF39: =VLOOKUP($D39,records!$A:$V,13,FALSE) -> KSB SAS | AG39: Facture originale électronique à | AH39: =VLOOKUP($D39,records!$A:$V,19,FALSE) -> ap_invoices_fr@ksb.com | AI39: . | AJ39: =VLOOKUP($O39,'records (2)'!$A:$Z,14,FALSE) -> 003IV000010su8fYAA | AK39: =VLOOKUP($O39,'records (2)'!$A:$Z,15,FALSE) -> Hervé DECROOS | AL39: =VLOOKUP($O39,'records (2)'!$A:$Z,10,FALSE) -> 003IV000010su8gYAA | AM39: =VLOOKUP($O39,'records (2)'!$A:$Z,11,FALSE) -> Valérie RAYNAUD | AN39: 1 | AO39: 500 | AP39: 500 | AQ39: 0 | AR39: 0
A40: IVCF-01793 | B40: INVACARE France | C40: INVACARE FRANCE OPERATIONS | D40: 001IV000015S2SUYA0 | E40: 01tIV00000GyVCbYAN | F40: Redevance d'utilisation - Tranche 25 ETP - Cas 2 | H40: Annual | I40: In advance | J40: 46023 | K40: 46387 | L40: Pixid France | M40: Pack C&S | N40: 46023 | O40: =VLOOKUP(D40,records!$A:$U,10,FALSE) -> 001SZ0000059VWTYA2 | P40: =VLOOKUP(D40,records!$A:$V,20,FALSE) -> FR19348418732 | Q40: =VLOOKUP(D40,records!$A:$V,12,FALSE) -> 34 841 873 200 049 | R40: Email | S40: =VLOOKUP(D40,records!$A:$U,19,FALSE) -> ap3110ivcfranceoperations@invacare.com | T40: Transfer | U40: Renewal | V40: =VLOOKUP($D40,records!$A:$V,3,FALSE) -> INVACARE FRANCE OPERATIONS SAS | X40: =VLOOKUP($D40,records!$A:$V,9,FALSE) -> Route de Saint- Roch | Y40: =VLOOKUP($D40,records!$A:$V,4,FALSE) -> FONDETTES | Z40: =VLOOKUP($D40,records!$A:$V,7,FALSE) -> 37230 | AA40: Redevance 2026 | AB40: =VLOOKUP(O40,'records (2)'!$A:$Z,8,FALSE) -> 30 | AC40: FALSE | AF40: =VLOOKUP($D40,records!$A:$V,13,FALSE) -> INVACARE FRANCE OPERATIONS SAS | AG40: Facture originale électronique à | AH40: =VLOOKUP($D40,records!$A:$V,19,FALSE) -> ap3110ivcfranceoperations@invacare.com | AI40: . | AJ40: =VLOOKUP($O40,'records (2)'!$A:$Z,14,FALSE) -> 003IV000010su8kYAA | AK40: =VLOOKUP($O40,'records (2)'!$A:$Z,15,FALSE) -> Stéphane CHEBROUX (ap3110ivcfr) | AL40: =VLOOKUP($O40,'records (2)'!$A:$Z,10,FALSE) -> 003IV000010su8kYAA | AM40: =VLOOKUP($O40,'records (2)'!$A:$Z,11,FALSE) -> Stéphane CHEBROUX (ap3110ivcfr) | AN40: 1 | AO40: 3000 | AP40: 3000 | AQ40: 0 | AR40: 0
